Dataset 10 uploaded by user bheng
CSV Content Preview (first 500 chars):

Error processing Dataset None: No columns to parse from file
Traceback (most recent call last):
  File "C:\xampp\htdocs\PilarEaseDJO\admin_tools\views.py", line 108, in performance_dashboard
    df = pd.read_csv(io.StringIO(content))
         ^^^^^^^^^^^^^^^^^^^^^^^^^^^^^^^^^
  File "C:\xampp\htdocs\PilarEaseDJO\.venv\Lib\site-packages\pandas\io\parsers\readers.py", line 1026, in read_csv
    return _read(filepath_or_buffer, kwds)
           ^^^^^^^^^^^^^^^^^^^^^^^^^^^^^^^
  File "C:\xampp\htdocs\PilarEaseDJO\.venv\Lib\site-packages\pandas\io\parsers\readers.py", line 620, in _read
    parser = TextFileReader(filepath_or_buffer, **kwds)
             ^^^^^^^^^^^^^^^^^^^^^^^^^^^^^^^^^^^^^^^^^^
  File "C:\xampp\htdocs\PilarEaseDJO\.venv\Lib\site-packages\pandas\io\parsers\readers.py", line 1620, in __init__
    self._engine = self._make_engine(f, self.engine)
                   ^^^^^^^^^^^^^^^^^^^^^^^^^^^^^^^^^
  File "C:\xampp\htdocs\PilarEaseDJO\.venv\Lib\site-packages\pandas\io\parsers\readers.py", line 1898, in _make_engine
    return mapping[engine](f, **self.options)
           ^^^^^^^^^^^^^^^^^^^^^^^^^^^^^^^^^^
  File "C:\xampp\htdocs\PilarEaseDJO\.venv\Lib\site-packages\pandas\io\parsers\c_parser_wrapper.py", line 93, in __init__
    self._reader = parsers.TextReader(src, **kwds)
                   ^^^^^^^^^^^^^^^^^^^^^^^^^^^^^^^
  File "parsers.pyx", line 581, in pandas._libs.parsers.TextReader.__cinit__
pandas.errors.EmptyDataError: No columns to parse from file
Dataset 11 uploaded by user bheng
CSV Content Preview (first 500 chars):

Error processing Dataset None: No columns to parse from file
Traceback (most recent call last):
  File "C:\xampp\htdocs\PilarEaseDJO\admin_tools\views.py", line 108, in performance_dashboard
    df = pd.read_csv(io.StringIO(content))
         ^^^^^^^^^^^^^^^^^^^^^^^^^^^^^^^^^
  File "C:\xampp\htdocs\PilarEaseDJO\.venv\Lib\site-packages\pandas\io\parsers\readers.py", line 1026, in read_csv
    return _read(filepath_or_buffer, kwds)
           ^^^^^^^^^^^^^^^^^^^^^^^^^^^^^^^
  File "C:\xampp\htdocs\PilarEaseDJO\.venv\Lib\site-packages\pandas\io\parsers\readers.py", line 620, in _read
    parser = TextFileReader(filepath_or_buffer, **kwds)
             ^^^^^^^^^^^^^^^^^^^^^^^^^^^^^^^^^^^^^^^^^^
  File "C:\xampp\htdocs\PilarEaseDJO\.venv\Lib\site-packages\pandas\io\parsers\readers.py", line 1620, in __init__
    self._engine = self._make_engine(f, self.engine)
                   ^^^^^^^^^^^^^^^^^^^^^^^^^^^^^^^^^
  File "C:\xampp\htdocs\PilarEaseDJO\.venv\Lib\site-packages\pandas\io\parsers\readers.py", line 1898, in _make_engine
    return mapping[engine](f, **self.options)
           ^^^^^^^^^^^^^^^^^^^^^^^^^^^^^^^^^^
  File "C:\xampp\htdocs\PilarEaseDJO\.venv\Lib\site-packages\pandas\io\parsers\c_parser_wrapper.py", line 93, in __init__
    self._reader = parsers.TextReader(src, **kwds)
                   ^^^^^^^^^^^^^^^^^^^^^^^^^^^^^^^
  File "parsers.pyx", line 581, in pandas._libs.parsers.TextReader.__cinit__
pandas.errors.EmptyDataError: No columns to parse from file
Dataset 12 uploaded by user bheng
Unexpected error processing Dataset None: No columns to parse from file
Traceback (most recent call last):
  File "C:\xampp\htdocs\PilarEaseDJO\admin_tools\views.py", line 94, in performance_dashboard
    df = pd.read_csv(csv_file)
         ^^^^^^^^^^^^^^^^^^^^^
  File "C:\xampp\htdocs\PilarEaseDJO\.venv\Lib\site-packages\pandas\io\parsers\readers.py", line 1026, in read_csv
    return _read(filepath_or_buffer, kwds)
           ^^^^^^^^^^^^^^^^^^^^^^^^^^^^^^^
  File "C:\xampp\htdocs\PilarEaseDJO\.venv\Lib\site-packages\pandas\io\parsers\readers.py", line 620, in _read
    parser = TextFileReader(filepath_or_buffer, **kwds)
             ^^^^^^^^^^^^^^^^^^^^^^^^^^^^^^^^^^^^^^^^^^
  File "C:\xampp\htdocs\PilarEaseDJO\.venv\Lib\site-packages\pandas\io\parsers\readers.py", line 1620, in __init__
    self._engine = self._make_engine(f, self.engine)
                   ^^^^^^^^^^^^^^^^^^^^^^^^^^^^^^^^^
  File "C:\xampp\htdocs\PilarEaseDJO\.venv\Lib\site-packages\pandas\io\parsers\readers.py", line 1898, in _make_engine
    return mapping[engine](f, **self.options)
           ^^^^^^^^^^^^^^^^^^^^^^^^^^^^^^^^^^
  File "C:\xampp\htdocs\PilarEaseDJO\.venv\Lib\site-packages\pandas\io\parsers\c_parser_wrapper.py", line 93, in __init__
    self._reader = parsers.TextReader(src, **kwds)
                   ^^^^^^^^^^^^^^^^^^^^^^^^^^^^^^^
  File "parsers.pyx", line 581, in pandas._libs.parsers.TextReader.__cinit__
pandas.errors.EmptyDataError: No columns to parse from file
Dataset 13 uploaded by user bheng
Unexpected error processing Dataset None: No columns to parse from file
Traceback (most recent call last):
  File "C:\xampp\htdocs\PilarEaseDJO\admin_tools\views.py", line 94, in performance_dashboard
    df = pd.read_csv(csv_file)
         ^^^^^^^^^^^^^^^^^^^^^
  File "C:\xampp\htdocs\PilarEaseDJO\.venv\Lib\site-packages\pandas\io\parsers\readers.py", line 1026, in read_csv
    return _read(filepath_or_buffer, kwds)
           ^^^^^^^^^^^^^^^^^^^^^^^^^^^^^^^
  File "C:\xampp\htdocs\PilarEaseDJO\.venv\Lib\site-packages\pandas\io\parsers\readers.py", line 620, in _read
    parser = TextFileReader(filepath_or_buffer, **kwds)
             ^^^^^^^^^^^^^^^^^^^^^^^^^^^^^^^^^^^^^^^^^^
  File "C:\xampp\htdocs\PilarEaseDJO\.venv\Lib\site-packages\pandas\io\parsers\readers.py", line 1620, in __init__
    self._engine = self._make_engine(f, self.engine)
                   ^^^^^^^^^^^^^^^^^^^^^^^^^^^^^^^^^
  File "C:\xampp\htdocs\PilarEaseDJO\.venv\Lib\site-packages\pandas\io\parsers\readers.py", line 1898, in _make_engine
    return mapping[engine](f, **self.options)
           ^^^^^^^^^^^^^^^^^^^^^^^^^^^^^^^^^^
  File "C:\xampp\htdocs\PilarEaseDJO\.venv\Lib\site-packages\pandas\io\parsers\c_parser_wrapper.py", line 93, in __init__
    self._reader = parsers.TextReader(src, **kwds)
                   ^^^^^^^^^^^^^^^^^^^^^^^^^^^^^^^
  File "parsers.pyx", line 581, in pandas._libs.parsers.TextReader.__cinit__
pandas.errors.EmptyDataError: No columns to parse from file
Dataset 14 uploaded by user bheng
Error processing Dataset None: No columns to parse from file
Traceback (most recent call last):
  File "C:\xampp\htdocs\PilarEaseDJO\admin_tools\views.py", line 101, in performance_dashboard
    df = pd.read_csv(csv_file)
         ^^^^^^^^^^^^^^^^^^^^^
  File "C:\xampp\htdocs\PilarEaseDJO\.venv\Lib\site-packages\pandas\io\parsers\readers.py", line 1026, in read_csv
    return _read(filepath_or_buffer, kwds)
           ^^^^^^^^^^^^^^^^^^^^^^^^^^^^^^^
  File "C:\xampp\htdocs\PilarEaseDJO\.venv\Lib\site-packages\pandas\io\parsers\readers.py", line 620, in _read
    parser = TextFileReader(filepath_or_buffer, **kwds)
             ^^^^^^^^^^^^^^^^^^^^^^^^^^^^^^^^^^^^^^^^^^
  File "C:\xampp\htdocs\PilarEaseDJO\.venv\Lib\site-packages\pandas\io\parsers\readers.py", line 1620, in __init__
    self._engine = self._make_engine(f, self.engine)
                   ^^^^^^^^^^^^^^^^^^^^^^^^^^^^^^^^^
  File "C:\xampp\htdocs\PilarEaseDJO\.venv\Lib\site-packages\pandas\io\parsers\readers.py", line 1898, in _make_engine
    return mapping[engine](f, **self.options)
           ^^^^^^^^^^^^^^^^^^^^^^^^^^^^^^^^^^
  File "C:\xampp\htdocs\PilarEaseDJO\.venv\Lib\site-packages\pandas\io\parsers\c_parser_wrapper.py", line 93, in __init__
    self._reader = parsers.TextReader(src, **kwds)
                   ^^^^^^^^^^^^^^^^^^^^^^^^^^^^^^^
  File "parsers.pyx", line 581, in pandas._libs.parsers.TextReader.__cinit__
pandas.errors.EmptyDataError: No columns to parse from file
Dataset 15 uploaded by user bheng
Error processing Dataset None: No columns to parse from file
Traceback (most recent call last):
  File "C:\xampp\htdocs\PilarEaseDJO\admin_tools\views.py", line 101, in performance_dashboard
    df = pd.read_csv(csv_file)
         ^^^^^^^^^^^^^^^^^^^^^
  File "C:\xampp\htdocs\PilarEaseDJO\.venv\Lib\site-packages\pandas\io\parsers\readers.py", line 1026, in read_csv
    return _read(filepath_or_buffer, kwds)
           ^^^^^^^^^^^^^^^^^^^^^^^^^^^^^^^
  File "C:\xampp\htdocs\PilarEaseDJO\.venv\Lib\site-packages\pandas\io\parsers\readers.py", line 620, in _read
    parser = TextFileReader(filepath_or_buffer, **kwds)
             ^^^^^^^^^^^^^^^^^^^^^^^^^^^^^^^^^^^^^^^^^^
  File "C:\xampp\htdocs\PilarEaseDJO\.venv\Lib\site-packages\pandas\io\parsers\readers.py", line 1620, in __init__
    self._engine = self._make_engine(f, self.engine)
                   ^^^^^^^^^^^^^^^^^^^^^^^^^^^^^^^^^
  File "C:\xampp\htdocs\PilarEaseDJO\.venv\Lib\site-packages\pandas\io\parsers\readers.py", line 1898, in _make_engine
    return mapping[engine](f, **self.options)
           ^^^^^^^^^^^^^^^^^^^^^^^^^^^^^^^^^^
  File "C:\xampp\htdocs\PilarEaseDJO\.venv\Lib\site-packages\pandas\io\parsers\c_parser_wrapper.py", line 93, in __init__
    self._reader = parsers.TextReader(src, **kwds)
                   ^^^^^^^^^^^^^^^^^^^^^^^^^^^^^^^
  File "parsers.pyx", line 581, in pandas._libs.parsers.TextReader.__cinit__
pandas.errors.EmptyDataError: No columns to parse from file
Dataset 16 uploaded by user bheng
CSV file read successfully with shape (114991, 2)
Unexpected error processing Dataset None: 'Text'
Traceback (most recent call last):
  File "C:\xampp\htdocs\PilarEaseDJO\.venv\Lib\site-packages\pandas\core\indexes\base.py", line 3805, in get_loc
    return self._engine.get_loc(casted_key)
           ^^^^^^^^^^^^^^^^^^^^^^^^^^^^^^^^
  File "index.pyx", line 167, in pandas._libs.index.IndexEngine.get_loc
  File "index.pyx", line 196, in pandas._libs.index.IndexEngine.get_loc
  File "pandas\\_libs\\hashtable_class_helper.pxi", line 7081, in pandas._libs.hashtable.PyObjectHashTable.get_item
  File "pandas\\_libs\\hashtable_class_helper.pxi", line 7089, in pandas._libs.hashtable.PyObjectHashTable.get_item
KeyError: 'Text'

The above exception was the direct cause of the following exception:

Traceback (most recent call last):
  File "C:\xampp\htdocs\PilarEaseDJO\admin_tools\views.py", line 105, in performance_dashboard
    X = df['Text']
        ~~^^^^^^^^
  File "C:\xampp\htdocs\PilarEaseDJO\.venv\Lib\site-packages\pandas\core\frame.py", line 4102, in __getitem__
    indexer = self.columns.get_loc(key)
              ^^^^^^^^^^^^^^^^^^^^^^^^^
  File "C:\xampp\htdocs\PilarEaseDJO\.venv\Lib\site-packages\pandas\core\indexes\base.py", line 3812, in get_loc
    raise KeyError(key) from err
KeyError: 'Text'
Dataset 17 uploaded by user bheng
CSV file read successfully with shape (38765, 2)
Data split into train and test sets.
Unexpected error processing Dataset None: jhartman/english-distillroberta-base-model is not a local folder and is not a valid model identifier listed on 'https://huggingface.co/models'
If this is a private repository, make sure to pass a token having permission to this repo either by logging in with `huggingface-cli login` or by passing `token=<your_token>`
Traceback (most recent call last):
  File "C:\xampp\htdocs\PilarEaseDJO\.venv\Lib\site-packages\huggingface_hub\utils\_errors.py", line 304, in hf_raise_for_status
    response.raise_for_status()
  File "C:\xampp\htdocs\PilarEaseDJO\.venv\Lib\site-packages\requests\models.py", line 1024, in raise_for_status
    raise HTTPError(http_error_msg, response=self)
requests.exceptions.HTTPError: 401 Client Error: Unauthorized for url: https://huggingface.co/jhartman/english-distillroberta-base-model/resolve/main/added_tokens.json

The above exception was the direct cause of the following exception:

Traceback (most recent call last):
  File "C:\xampp\htdocs\PilarEaseDJO\.venv\Lib\site-packages\transformers\utils\hub.py", line 399, in cached_file
    resolved_file = hf_hub_download(
                    ^^^^^^^^^^^^^^^^
  File "C:\xampp\htdocs\PilarEaseDJO\.venv\Lib\site-packages\huggingface_hub\utils\_validators.py", line 114, in _inner_fn
    return fn(*args, **kwargs)
           ^^^^^^^^^^^^^^^^^^^
  File "C:\xampp\htdocs\PilarEaseDJO\.venv\Lib\site-packages\huggingface_hub\file_download.py", line 1221, in hf_hub_download
    return _hf_hub_download_to_cache_dir(
           ^^^^^^^^^^^^^^^^^^^^^^^^^^^^^^
  File "C:\xampp\htdocs\PilarEaseDJO\.venv\Lib\site-packages\huggingface_hub\file_download.py", line 1325, in _hf_hub_download_to_cache_dir
    _raise_on_head_call_error(head_call_error, force_download, local_files_only)
  File "C:\xampp\htdocs\PilarEaseDJO\.venv\Lib\site-packages\huggingface_hub\file_download.py", line 1823, in _raise_on_head_call_error
    raise head_call_error
  File "C:\xampp\htdocs\PilarEaseDJO\.venv\Lib\site-packages\huggingface_hub\file_download.py", line 1722, in _get_metadata_or_catch_error
    metadata = get_hf_file_metadata(url=url, proxies=proxies, timeout=etag_timeout, headers=headers)
               ^^^^^^^^^^^^^^^^^^^^^^^^^^^^^^^^^^^^^^^^^^^^^^^^^^^^^^^^^^^^^^^^^^^^^^^^^^^^^^^^^^^^^
  File "C:\xampp\htdocs\PilarEaseDJO\.venv\Lib\site-packages\huggingface_hub\utils\_validators.py", line 114, in _inner_fn
    return fn(*args, **kwargs)
           ^^^^^^^^^^^^^^^^^^^
  File "C:\xampp\htdocs\PilarEaseDJO\.venv\Lib\site-packages\huggingface_hub\file_download.py", line 1645, in get_hf_file_metadata
    r = _request_wrapper(
        ^^^^^^^^^^^^^^^^^
  File "C:\xampp\htdocs\PilarEaseDJO\.venv\Lib\site-packages\huggingface_hub\file_download.py", line 372, in _request_wrapper
    response = _request_wrapper(
               ^^^^^^^^^^^^^^^^^
  File "C:\xampp\htdocs\PilarEaseDJO\.venv\Lib\site-packages\huggingface_hub\file_download.py", line 396, in _request_wrapper
    hf_raise_for_status(response)
  File "C:\xampp\htdocs\PilarEaseDJO\.venv\Lib\site-packages\huggingface_hub\utils\_errors.py", line 352, in hf_raise_for_status
    raise RepositoryNotFoundError(message, response) from e
huggingface_hub.utils._errors.RepositoryNotFoundError: 401 Client Error. (Request ID: Root=1-6711eb54-0cca996f4b5bb55c55b4f79e;be9d8e4c-a0b6-4d8d-ae71-ce371cd18ce8)

Repository Not Found for url: https://huggingface.co/jhartman/english-distillroberta-base-model/resolve/main/added_tokens.json.
Please make sure you specified the correct `repo_id` and `repo_type`.
If you are trying to access a private or gated repo, make sure you are authenticated.
Invalid username or password.

The above exception was the direct cause of the following exception:

Traceback (most recent call last):
  File "C:\xampp\htdocs\PilarEaseDJO\admin_tools\views.py", line 123, in performance_dashboard
    tokenizer = DistilBertTokenizer.from_pretrained(model_name)
                ^^^^^^^^^^^^^^^^^^^^^^^^^^^^^^^^^^^^^^^^^^^^^^^
  File "C:\xampp\htdocs\PilarEaseDJO\.venv\Lib\site-packages\transformers\tokenization_utils_base.py", line 2066, in from_pretrained
    resolved_vocab_files[file_id] = cached_file(
                                    ^^^^^^^^^^^^
  File "C:\xampp\htdocs\PilarEaseDJO\.venv\Lib\site-packages\transformers\utils\hub.py", line 422, in cached_file
    raise EnvironmentError(
OSError: jhartman/english-distillroberta-base-model is not a local folder and is not a valid model identifier listed on 'https://huggingface.co/models'
If this is a private repository, make sure to pass a token having permission to this repo either by logging in with `huggingface-cli login` or by passing `token=<your_token>`
Dataset 18 uploaded by user bheng
CSV file read successfully with shape (38765, 2)
Data split into train and test sets.
Unexpected error processing Dataset None: jhartman/english-distillroberta-base-model is not a local folder and is not a valid model identifier listed on 'https://huggingface.co/models'
If this is a private repository, make sure to pass a token having permission to this repo either by logging in with `huggingface-cli login` or by passing `token=<your_token>`
Traceback (most recent call last):
  File "C:\xampp\htdocs\PilarEaseDJO\.venv\Lib\site-packages\huggingface_hub\utils\_errors.py", line 304, in hf_raise_for_status
    response.raise_for_status()
  File "C:\xampp\htdocs\PilarEaseDJO\.venv\Lib\site-packages\requests\models.py", line 1024, in raise_for_status
    raise HTTPError(http_error_msg, response=self)
requests.exceptions.HTTPError: 401 Client Error: Unauthorized for url: https://huggingface.co/jhartman/english-distillroberta-base-model/resolve/main/tokenizer_config.json

The above exception was the direct cause of the following exception:

Traceback (most recent call last):
  File "C:\xampp\htdocs\PilarEaseDJO\.venv\Lib\site-packages\transformers\utils\hub.py", line 399, in cached_file
    resolved_file = hf_hub_download(
                    ^^^^^^^^^^^^^^^^
  File "C:\xampp\htdocs\PilarEaseDJO\.venv\Lib\site-packages\huggingface_hub\utils\_validators.py", line 114, in _inner_fn
    return fn(*args, **kwargs)
           ^^^^^^^^^^^^^^^^^^^
  File "C:\xampp\htdocs\PilarEaseDJO\.venv\Lib\site-packages\huggingface_hub\file_download.py", line 1221, in hf_hub_download
    return _hf_hub_download_to_cache_dir(
           ^^^^^^^^^^^^^^^^^^^^^^^^^^^^^^
  File "C:\xampp\htdocs\PilarEaseDJO\.venv\Lib\site-packages\huggingface_hub\file_download.py", line 1325, in _hf_hub_download_to_cache_dir
    _raise_on_head_call_error(head_call_error, force_download, local_files_only)
  File "C:\xampp\htdocs\PilarEaseDJO\.venv\Lib\site-packages\huggingface_hub\file_download.py", line 1823, in _raise_on_head_call_error
    raise head_call_error
  File "C:\xampp\htdocs\PilarEaseDJO\.venv\Lib\site-packages\huggingface_hub\file_download.py", line 1722, in _get_metadata_or_catch_error
    metadata = get_hf_file_metadata(url=url, proxies=proxies, timeout=etag_timeout, headers=headers)
               ^^^^^^^^^^^^^^^^^^^^^^^^^^^^^^^^^^^^^^^^^^^^^^^^^^^^^^^^^^^^^^^^^^^^^^^^^^^^^^^^^^^^^
  File "C:\xampp\htdocs\PilarEaseDJO\.venv\Lib\site-packages\huggingface_hub\utils\_validators.py", line 114, in _inner_fn
    return fn(*args, **kwargs)
           ^^^^^^^^^^^^^^^^^^^
  File "C:\xampp\htdocs\PilarEaseDJO\.venv\Lib\site-packages\huggingface_hub\file_download.py", line 1645, in get_hf_file_metadata
    r = _request_wrapper(
        ^^^^^^^^^^^^^^^^^
  File "C:\xampp\htdocs\PilarEaseDJO\.venv\Lib\site-packages\huggingface_hub\file_download.py", line 372, in _request_wrapper
    response = _request_wrapper(
               ^^^^^^^^^^^^^^^^^
  File "C:\xampp\htdocs\PilarEaseDJO\.venv\Lib\site-packages\huggingface_hub\file_download.py", line 396, in _request_wrapper
    hf_raise_for_status(response)
  File "C:\xampp\htdocs\PilarEaseDJO\.venv\Lib\site-packages\huggingface_hub\utils\_errors.py", line 352, in hf_raise_for_status
    raise RepositoryNotFoundError(message, response) from e
huggingface_hub.utils._errors.RepositoryNotFoundError: 401 Client Error. (Request ID: Root=1-6711ebf9-6be750ac7d38ef457fccb9df;f02ae2ac-2b25-4c14-8fd7-f91b48cd2166)

Repository Not Found for url: https://huggingface.co/jhartman/english-distillroberta-base-model/resolve/main/tokenizer_config.json.
Please make sure you specified the correct `repo_id` and `repo_type`.
If you are trying to access a private or gated repo, make sure you are authenticated.
Invalid username or password.

The above exception was the direct cause of the following exception:

Traceback (most recent call last):
  File "C:\xampp\htdocs\PilarEaseDJO\admin_tools\views.py", line 123, in performance_dashboard
    tokenizer = DistilBertTokenizer.from_pretrained(model_name)
                ^^^^^^^^^^^^^^^^^^^^^^^^^^^^^^^^^^^^^^^^^^^^^^^
  File "C:\xampp\htdocs\PilarEaseDJO\.venv\Lib\site-packages\transformers\tokenization_utils_base.py", line 2029, in from_pretrained
    resolved_config_file = cached_file(
                           ^^^^^^^^^^^^
  File "C:\xampp\htdocs\PilarEaseDJO\.venv\Lib\site-packages\transformers\utils\hub.py", line 422, in cached_file
    raise EnvironmentError(
OSError: jhartman/english-distillroberta-base-model is not a local folder and is not a valid model identifier listed on 'https://huggingface.co/models'
If this is a private repository, make sure to pass a token having permission to this repo either by logging in with `huggingface-cli login` or by passing `token=<your_token>`
Dataset 19 uploaded by user bheng
CSV file read successfully with shape (38765, 2)
Data split into train and test sets.
Unexpected error processing Dataset None: isfile: path should be string, bytes, os.PathLike or integer, not NoneType
Traceback (most recent call last):
  File "C:\xampp\htdocs\PilarEaseDJO\admin_tools\views.py", line 123, in performance_dashboard
    tokenizer = DistilBertTokenizer.from_pretrained(model_name)
                ^^^^^^^^^^^^^^^^^^^^^^^^^^^^^^^^^^^^^^^^^^^^^^^
  File "C:\xampp\htdocs\PilarEaseDJO\.venv\Lib\site-packages\transformers\tokenization_utils_base.py", line 2110, in from_pretrained
    return cls._from_pretrained(
           ^^^^^^^^^^^^^^^^^^^^^
  File "C:\xampp\htdocs\PilarEaseDJO\.venv\Lib\site-packages\transformers\tokenization_utils_base.py", line 2336, in _from_pretrained
    tokenizer = cls(*init_inputs, **init_kwargs)
                ^^^^^^^^^^^^^^^^^^^^^^^^^^^^^^^^
  File "C:\xampp\htdocs\PilarEaseDJO\.venv\Lib\site-packages\transformers\models\distilbert\tokenization_distilbert.py", line 113, in __init__
    if not os.path.isfile(vocab_file):
           ^^^^^^^^^^^^^^^^^^^^^^^^^^
TypeError: isfile: path should be string, bytes, os.PathLike or integer, not NoneType
Dataset 20 uploaded by user bheng
CSV file read successfully with shape (38765, 2)
Data split into train and test sets.
Model and tokenizer loaded from 'j-hartmann/emotion-english-distilroberta-base'
Unexpected error processing Dataset None: 'Series' object has no attribute 'iteritems'
Traceback (most recent call last):
  File "C:\xampp\htdocs\PilarEaseDJO\admin_tools\views.py", line 139, in performance_dashboard
    for idx, text in X_test.iteritems():  # X_test is a Series
                     ^^^^^^^^^^^^^^^^
  File "C:\xampp\htdocs\PilarEaseDJO\.venv\Lib\site-packages\pandas\core\generic.py", line 6299, in __getattr__
    return object.__getattribute__(self, name)
           ^^^^^^^^^^^^^^^^^^^^^^^^^^^^^^^^^^^
AttributeError: 'Series' object has no attribute 'iteritems'
Dataset 21 uploaded by user bheng
CSV file read successfully with shape (38765, 2)
Data split into train and test sets.
Model and tokenizer loaded from 'j-hartmann/emotion-english-distilroberta-base'
Error processing dataset 24: Mix of label input types (string and number)
Traceback (most recent call last):
  File "C:\xampp\htdocs\PilarEaseDJO\admin_tools\views.py", line 189, in process_dataset
    precision = precision_score(y_test_clean, y_pred_clean, average='weighted', zero_division=0)
                ^^^^^^^^^^^^^^^^^^^^^^^^^^^^^^^^^^^^^^^^^^^^^^^^^^^^^^^^^^^^^^^^^^^^^^^^^^^^^^^^
  File "C:\xampp\htdocs\PilarEaseDJO\.venv\Lib\site-packages\sklearn\utils\_param_validation.py", line 213, in wrapper
    return func(*args, **kwargs)
           ^^^^^^^^^^^^^^^^^^^^^
  File "C:\xampp\htdocs\PilarEaseDJO\.venv\Lib\site-packages\sklearn\metrics\_classification.py", line 2190, in precision_score
    p, _, _, _ = precision_recall_fscore_support(
                 ^^^^^^^^^^^^^^^^^^^^^^^^^^^^^^^^
  File "C:\xampp\htdocs\PilarEaseDJO\.venv\Lib\site-packages\sklearn\utils\_param_validation.py", line 186, in wrapper
    return func(*args, **kwargs)
           ^^^^^^^^^^^^^^^^^^^^^
  File "C:\xampp\htdocs\PilarEaseDJO\.venv\Lib\site-packages\sklearn\metrics\_classification.py", line 1775, in precision_recall_fscore_support
    labels = _check_set_wise_labels(y_true, y_pred, average, labels, pos_label)
             ^^^^^^^^^^^^^^^^^^^^^^^^^^^^^^^^^^^^^^^^^^^^^^^^^^^^^^^^^^^^^^^^^^
  File "C:\xampp\htdocs\PilarEaseDJO\.venv\Lib\site-packages\sklearn\metrics\_classification.py", line 1550, in _check_set_wise_labels
    present_labels = unique_labels(y_true, y_pred).tolist()
                     ^^^^^^^^^^^^^^^^^^^^^^^^^^^^^
  File "C:\xampp\htdocs\PilarEaseDJO\.venv\Lib\site-packages\sklearn\utils\multiclass.py", line 116, in unique_labels
    raise ValueError("Mix of label input types (string and number)")
ValueError: Mix of label input types (string and number)
Error processing dataset 25: Mix of label input types (string and number)
Traceback (most recent call last):
  File "C:\xampp\htdocs\PilarEaseDJO\admin_tools\views.py", line 189, in process_dataset
    precision = precision_score(y_test_clean, y_pred_clean, average='weighted', zero_division=0)
                ^^^^^^^^^^^^^^^^^^^^^^^^^^^^^^^^^^^^^^^^^^^^^^^^^^^^^^^^^^^^^^^^^^^^^^^^^^^^^^^^
  File "C:\xampp\htdocs\PilarEaseDJO\.venv\Lib\site-packages\sklearn\utils\_param_validation.py", line 213, in wrapper
    return func(*args, **kwargs)
           ^^^^^^^^^^^^^^^^^^^^^
  File "C:\xampp\htdocs\PilarEaseDJO\.venv\Lib\site-packages\sklearn\metrics\_classification.py", line 2190, in precision_score
    p, _, _, _ = precision_recall_fscore_support(
                 ^^^^^^^^^^^^^^^^^^^^^^^^^^^^^^^^
  File "C:\xampp\htdocs\PilarEaseDJO\.venv\Lib\site-packages\sklearn\utils\_param_validation.py", line 186, in wrapper
    return func(*args, **kwargs)
           ^^^^^^^^^^^^^^^^^^^^^
  File "C:\xampp\htdocs\PilarEaseDJO\.venv\Lib\site-packages\sklearn\metrics\_classification.py", line 1775, in precision_recall_fscore_support
    labels = _check_set_wise_labels(y_true, y_pred, average, labels, pos_label)
             ^^^^^^^^^^^^^^^^^^^^^^^^^^^^^^^^^^^^^^^^^^^^^^^^^^^^^^^^^^^^^^^^^^
  File "C:\xampp\htdocs\PilarEaseDJO\.venv\Lib\site-packages\sklearn\metrics\_classification.py", line 1550, in _check_set_wise_labels
    present_labels = unique_labels(y_true, y_pred).tolist()
                     ^^^^^^^^^^^^^^^^^^^^^^^^^^^^^
  File "C:\xampp\htdocs\PilarEaseDJO\.venv\Lib\site-packages\sklearn\utils\multiclass.py", line 116, in unique_labels
    raise ValueError("Mix of label input types (string and number)")
ValueError: Mix of label input types (string and number)
Error processing dataset 26: Mix of label input types (string and number)
Traceback (most recent call last):
  File "C:\xampp\htdocs\PilarEaseDJO\admin_tools\views.py", line 189, in process_dataset
    precision = precision_score(y_test_clean, y_pred_clean, average='weighted', zero_division=0)
                ^^^^^^^^^^^^^^^^^^^^^^^^^^^^^^^^^^^^^^^^^^^^^^^^^^^^^^^^^^^^^^^^^^^^^^^^^^^^^^^^
  File "C:\xampp\htdocs\PilarEaseDJO\.venv\Lib\site-packages\sklearn\utils\_param_validation.py", line 213, in wrapper
    return func(*args, **kwargs)
           ^^^^^^^^^^^^^^^^^^^^^
  File "C:\xampp\htdocs\PilarEaseDJO\.venv\Lib\site-packages\sklearn\metrics\_classification.py", line 2190, in precision_score
    p, _, _, _ = precision_recall_fscore_support(
                 ^^^^^^^^^^^^^^^^^^^^^^^^^^^^^^^^
  File "C:\xampp\htdocs\PilarEaseDJO\.venv\Lib\site-packages\sklearn\utils\_param_validation.py", line 186, in wrapper
    return func(*args, **kwargs)
           ^^^^^^^^^^^^^^^^^^^^^
  File "C:\xampp\htdocs\PilarEaseDJO\.venv\Lib\site-packages\sklearn\metrics\_classification.py", line 1775, in precision_recall_fscore_support
    labels = _check_set_wise_labels(y_true, y_pred, average, labels, pos_label)
             ^^^^^^^^^^^^^^^^^^^^^^^^^^^^^^^^^^^^^^^^^^^^^^^^^^^^^^^^^^^^^^^^^^
  File "C:\xampp\htdocs\PilarEaseDJO\.venv\Lib\site-packages\sklearn\metrics\_classification.py", line 1550, in _check_set_wise_labels
    present_labels = unique_labels(y_true, y_pred).tolist()
                     ^^^^^^^^^^^^^^^^^^^^^^^^^^^^^
  File "C:\xampp\htdocs\PilarEaseDJO\.venv\Lib\site-packages\sklearn\utils\multiclass.py", line 116, in unique_labels
    raise ValueError("Mix of label input types (string and number)")
ValueError: Mix of label input types (string and number)
Error processing dataset 27: Mix of label input types (string and number)
Traceback (most recent call last):
  File "C:\xampp\htdocs\PilarEaseDJO\admin_tools\views.py", line 189, in process_dataset
    precision = precision_score(y_test_clean, y_pred_clean, average='weighted', zero_division=0)
                ^^^^^^^^^^^^^^^^^^^^^^^^^^^^^^^^^^^^^^^^^^^^^^^^^^^^^^^^^^^^^^^^^^^^^^^^^^^^^^^^
  File "C:\xampp\htdocs\PilarEaseDJO\.venv\Lib\site-packages\sklearn\utils\_param_validation.py", line 213, in wrapper
    return func(*args, **kwargs)
           ^^^^^^^^^^^^^^^^^^^^^
  File "C:\xampp\htdocs\PilarEaseDJO\.venv\Lib\site-packages\sklearn\metrics\_classification.py", line 2190, in precision_score
    p, _, _, _ = precision_recall_fscore_support(
                 ^^^^^^^^^^^^^^^^^^^^^^^^^^^^^^^^
  File "C:\xampp\htdocs\PilarEaseDJO\.venv\Lib\site-packages\sklearn\utils\_param_validation.py", line 186, in wrapper
    return func(*args, **kwargs)
           ^^^^^^^^^^^^^^^^^^^^^
  File "C:\xampp\htdocs\PilarEaseDJO\.venv\Lib\site-packages\sklearn\metrics\_classification.py", line 1775, in precision_recall_fscore_support
    labels = _check_set_wise_labels(y_true, y_pred, average, labels, pos_label)
             ^^^^^^^^^^^^^^^^^^^^^^^^^^^^^^^^^^^^^^^^^^^^^^^^^^^^^^^^^^^^^^^^^^
  File "C:\xampp\htdocs\PilarEaseDJO\.venv\Lib\site-packages\sklearn\metrics\_classification.py", line 1550, in _check_set_wise_labels
    present_labels = unique_labels(y_true, y_pred).tolist()
                     ^^^^^^^^^^^^^^^^^^^^^^^^^^^^^
  File "C:\xampp\htdocs\PilarEaseDJO\.venv\Lib\site-packages\sklearn\utils\multiclass.py", line 116, in unique_labels
    raise ValueError("Mix of label input types (string and number)")
ValueError: Mix of label input types (string and number)
Fetching progress for Dataset ID 28: {'current_task': 'Uploading', 'percentage': 0}
Fetching progress for Dataset ID 28: {'current_task': 'Uploading', 'percentage': 0}
Fetching progress for Dataset ID 28: {'current_task': 'Uploading', 'percentage': 0}
Fetching progress for Dataset ID 28: {'current_task': 'Uploading', 'percentage': 0}
Fetching progress for Dataset ID 28: {'current_task': 'Uploading', 'percentage': 0}
Fetching progress for Dataset ID 28: {'current_task': 'Uploading', 'percentage': 0}
Fetching progress for Dataset ID 28: {'current_task': 'Uploading', 'percentage': 0}
Fetching progress for Dataset ID 28: {'current_task': 'Uploading', 'percentage': 0}
Fetching progress for Dataset ID 28: {'current_task': 'Uploading', 'percentage': 0}
Fetching progress for Dataset ID 28: {'current_task': 'Uploading', 'percentage': 0}
PerformanceResult created with ID 1 for Dataset 28.
Dataset 28 processed successfully.
Fetching progress for Dataset ID 28: {'current_task': 'Completed', 'percentage': 100, 'result_id': 1}
Error processing dataset 29: 'Text'
Traceback (most recent call last):
  File "C:\xampp\htdocs\PilarEaseDJO\.venv\Lib\site-packages\pandas\core\indexes\base.py", line 3805, in get_loc
    return self._engine.get_loc(casted_key)
           ^^^^^^^^^^^^^^^^^^^^^^^^^^^^^^^^
  File "index.pyx", line 167, in pandas._libs.index.IndexEngine.get_loc
  File "index.pyx", line 196, in pandas._libs.index.IndexEngine.get_loc
  File "pandas\\_libs\\hashtable_class_helper.pxi", line 7081, in pandas._libs.hashtable.PyObjectHashTable.get_item
  File "pandas\\_libs\\hashtable_class_helper.pxi", line 7089, in pandas._libs.hashtable.PyObjectHashTable.get_item
KeyError: 'Text'

The above exception was the direct cause of the following exception:

Traceback (most recent call last):
  File "C:\xampp\htdocs\PilarEaseDJO\admin_tools\views.py", line 138, in process_dataset
    X = df['Text']
        ~~^^^^^^^^
  File "C:\xampp\htdocs\PilarEaseDJO\.venv\Lib\site-packages\pandas\core\frame.py", line 4102, in __getitem__
    indexer = self.columns.get_loc(key)
              ^^^^^^^^^^^^^^^^^^^^^^^^^
  File "C:\xampp\htdocs\PilarEaseDJO\.venv\Lib\site-packages\pandas\core\indexes\base.py", line 3812, in get_loc
    raise KeyError(key) from err
KeyError: 'Text'
Fetching progress for Dataset ID 29: {'current_task': "Error: 'Text'", 'percentage': 100}
Fetching progress for Dataset ID 30: {'current_task': 'Uploading', 'percentage': 0}
Fetching progress for Dataset ID 30: {'current_task': 'Uploading', 'percentage': 0}
Fetching progress for Dataset ID 30: {'current_task': 'Uploading', 'percentage': 0}
Fetching progress for Dataset ID 30: {'current_task': 'Uploading', 'percentage': 0}
Fetching progress for Dataset ID 30: {'current_task': 'Uploading', 'percentage': 0}
Fetching progress for Dataset ID 30: {'current_task': 'Uploading', 'percentage': 0}
Fetching progress for Dataset ID 30: {'current_task': 'Uploading', 'percentage': 0}
PerformanceResult created with ID 2 for Dataset 30.
Dataset 30 processed successfully.
Fetching progress for Dataset ID 30: {'current_task': 'Completed', 'percentage': 100, 'result_id': 2}
Fetching progress for Dataset ID 31: {'current_task': 'Error: Null values found', 'percentage': 100}
Fetching progress for Dataset ID 32: {'current_task': 'Error: Null values found', 'percentage': 100}
Fetching progress for Dataset ID 33: {'current_task': 'Error: Null values found', 'percentage': 100}
Fetching progress for Dataset ID 34: {'current_task': 'Error: Null values found', 'percentage': 100}
Fetching progress for Dataset ID 35: {'current_task': 'Error: Null values found', 'percentage': 100}
Fetching progress for Dataset ID 36: {'current_task': 'Uploading', 'percentage': 0}
Fetching progress for Dataset ID 36: {'current_task': 'Uploading', 'percentage': 0}
Fetching progress for Dataset ID 36: {'current_task': 'Uploading', 'percentage': 0}
Fetching progress for Dataset ID 36: {'current_task': 'Uploading', 'percentage': 0}
Fetching progress for Dataset ID 36: {'current_task': 'Uploading', 'percentage': 0}
Fetching progress for Dataset ID 36: {'current_task': 'Uploading', 'percentage': 0}
PerformanceResult created with ID 3 for Dataset 36.
Dataset 36 processed successfully.
Fetching progress for Dataset ID 36: {'current_task': 'Completed', 'percentage': 100, 'result_id': 3}
Error processing dataset 37: Mix of label input types (string and number)
Traceback (most recent call last):
  File "C:\xampp\htdocs\PilarEaseDJO\admin_tools\views.py", line 189, in process_dataset
    precision = precision_score(y_test_clean, y_pred_clean, average='weighted', zero_division=0)
                ^^^^^^^^^^^^^^^^^^^^^^^^^^^^^^^^^^^^^^^^^^^^^^^^^^^^^^^^^^^^^^^^^^^^^^^^^^^^^^^^
  File "C:\xampp\htdocs\PilarEaseDJO\.venv\Lib\site-packages\sklearn\utils\_param_validation.py", line 213, in wrapper
    return func(*args, **kwargs)
           ^^^^^^^^^^^^^^^^^^^^^
  File "C:\xampp\htdocs\PilarEaseDJO\.venv\Lib\site-packages\sklearn\metrics\_classification.py", line 2190, in precision_score
    p, _, _, _ = precision_recall_fscore_support(
                 ^^^^^^^^^^^^^^^^^^^^^^^^^^^^^^^^
  File "C:\xampp\htdocs\PilarEaseDJO\.venv\Lib\site-packages\sklearn\utils\_param_validation.py", line 186, in wrapper
    return func(*args, **kwargs)
           ^^^^^^^^^^^^^^^^^^^^^
  File "C:\xampp\htdocs\PilarEaseDJO\.venv\Lib\site-packages\sklearn\metrics\_classification.py", line 1775, in precision_recall_fscore_support
    labels = _check_set_wise_labels(y_true, y_pred, average, labels, pos_label)
             ^^^^^^^^^^^^^^^^^^^^^^^^^^^^^^^^^^^^^^^^^^^^^^^^^^^^^^^^^^^^^^^^^^
  File "C:\xampp\htdocs\PilarEaseDJO\.venv\Lib\site-packages\sklearn\metrics\_classification.py", line 1550, in _check_set_wise_labels
    present_labels = unique_labels(y_true, y_pred).tolist()
                     ^^^^^^^^^^^^^^^^^^^^^^^^^^^^^
  File "C:\xampp\htdocs\PilarEaseDJO\.venv\Lib\site-packages\sklearn\utils\multiclass.py", line 116, in unique_labels
    raise ValueError("Mix of label input types (string and number)")
ValueError: Mix of label input types (string and number)
Error processing dataset 39: Mix of label input types (string and number)
Traceback (most recent call last):
  File "C:\xampp\htdocs\PilarEaseDJO\admin_tools\views.py", line 189, in process_dataset
    precision = precision_score(y_test_clean, y_pred_clean, average='weighted', zero_division=0)
                ^^^^^^^^^^^^^^^^^^^^^^^^^^^^^^^^^^^^^^^^^^^^^^^^^^^^^^^^^^^^^^^^^^^^^^^^^^^^^^^^
  File "C:\xampp\htdocs\PilarEaseDJO\.venv\Lib\site-packages\sklearn\utils\_param_validation.py", line 213, in wrapper
    return func(*args, **kwargs)
           ^^^^^^^^^^^^^^^^^^^^^
  File "C:\xampp\htdocs\PilarEaseDJO\.venv\Lib\site-packages\sklearn\metrics\_classification.py", line 2190, in precision_score
    p, _, _, _ = precision_recall_fscore_support(
                 ^^^^^^^^^^^^^^^^^^^^^^^^^^^^^^^^
  File "C:\xampp\htdocs\PilarEaseDJO\.venv\Lib\site-packages\sklearn\utils\_param_validation.py", line 186, in wrapper
    return func(*args, **kwargs)
           ^^^^^^^^^^^^^^^^^^^^^
  File "C:\xampp\htdocs\PilarEaseDJO\.venv\Lib\site-packages\sklearn\metrics\_classification.py", line 1775, in precision_recall_fscore_support
    labels = _check_set_wise_labels(y_true, y_pred, average, labels, pos_label)
             ^^^^^^^^^^^^^^^^^^^^^^^^^^^^^^^^^^^^^^^^^^^^^^^^^^^^^^^^^^^^^^^^^^
  File "C:\xampp\htdocs\PilarEaseDJO\.venv\Lib\site-packages\sklearn\metrics\_classification.py", line 1550, in _check_set_wise_labels
    present_labels = unique_labels(y_true, y_pred).tolist()
                     ^^^^^^^^^^^^^^^^^^^^^^^^^^^^^
  File "C:\xampp\htdocs\PilarEaseDJO\.venv\Lib\site-packages\sklearn\utils\multiclass.py", line 116, in unique_labels
    raise ValueError("Mix of label input types (string and number)")
ValueError: Mix of label input types (string and number)
Error processing dataset 40: Mix of label input types (string and number)
Traceback (most recent call last):
  File "C:\xampp\htdocs\PilarEaseDJO\admin_tools\views.py", line 189, in process_dataset
    precision = precision_score(y_test_clean, y_pred_clean, average='weighted', zero_division=0)
                ^^^^^^^^^^^^^^^^^^^^^^^^^^^^^^^^^^^^^^^^^^^^^^^^^^^^^^^^^^^^^^^^^^^^^^^^^^^^^^^^
  File "C:\xampp\htdocs\PilarEaseDJO\.venv\Lib\site-packages\sklearn\utils\_param_validation.py", line 213, in wrapper
    return func(*args, **kwargs)
           ^^^^^^^^^^^^^^^^^^^^^
  File "C:\xampp\htdocs\PilarEaseDJO\.venv\Lib\site-packages\sklearn\metrics\_classification.py", line 2190, in precision_score
    p, _, _, _ = precision_recall_fscore_support(
                 ^^^^^^^^^^^^^^^^^^^^^^^^^^^^^^^^
  File "C:\xampp\htdocs\PilarEaseDJO\.venv\Lib\site-packages\sklearn\utils\_param_validation.py", line 186, in wrapper
    return func(*args, **kwargs)
           ^^^^^^^^^^^^^^^^^^^^^
  File "C:\xampp\htdocs\PilarEaseDJO\.venv\Lib\site-packages\sklearn\metrics\_classification.py", line 1775, in precision_recall_fscore_support
    labels = _check_set_wise_labels(y_true, y_pred, average, labels, pos_label)
             ^^^^^^^^^^^^^^^^^^^^^^^^^^^^^^^^^^^^^^^^^^^^^^^^^^^^^^^^^^^^^^^^^^
  File "C:\xampp\htdocs\PilarEaseDJO\.venv\Lib\site-packages\sklearn\metrics\_classification.py", line 1550, in _check_set_wise_labels
    present_labels = unique_labels(y_true, y_pred).tolist()
                     ^^^^^^^^^^^^^^^^^^^^^^^^^^^^^
  File "C:\xampp\htdocs\PilarEaseDJO\.venv\Lib\site-packages\sklearn\utils\multiclass.py", line 116, in unique_labels
    raise ValueError("Mix of label input types (string and number)")
ValueError: Mix of label input types (string and number)
