2024-06-22 19:24:47,141:ERROR:An error occurred in main: [Errno 2] No such file or directory: 'emotion_datasets_predicted.csv'
Traceback: Traceback (most recent call last):
  File "c:\xampp\htdocs\PilarEaseDJO\data\translation\data-translation.py", line 187, in main
    df = pd.read_csv(dataset_path)
         ^^^^^^^^^^^^^^^^^^^^^^^^^
  File "C:\xampp\htdocs\PilarEaseDJO\.venv\Lib\site-packages\pandas\io\parsers\readers.py", line 1026, in read_csv
    return _read(filepath_or_buffer, kwds)
           ^^^^^^^^^^^^^^^^^^^^^^^^^^^^^^^
  File "C:\xampp\htdocs\PilarEaseDJO\.venv\Lib\site-packages\pandas\io\parsers\readers.py", line 620, in _read
    parser = TextFileReader(filepath_or_buffer, **kwds)
             ^^^^^^^^^^^^^^^^^^^^^^^^^^^^^^^^^^^^^^^^^^
  File "C:\xampp\htdocs\PilarEaseDJO\.venv\Lib\site-packages\pandas\io\parsers\readers.py", line 1620, in __init__
    self._engine = self._make_engine(f, self.engine)
                   ^^^^^^^^^^^^^^^^^^^^^^^^^^^^^^^^^
  File "C:\xampp\htdocs\PilarEaseDJO\.venv\Lib\site-packages\pandas\io\parsers\readers.py", line 1880, in _make_engine
    self.handles = get_handle(
                   ^^^^^^^^^^^
  File "C:\xampp\htdocs\PilarEaseDJO\.venv\Lib\site-packages\pandas\io\common.py", line 873, in get_handle
    handle = open(
             ^^^^^
FileNotFoundError: [Errno 2] No such file or directory: 'emotion_datasets_predicted.csv'

2024-06-22 19:24:56,660:ERROR:An error occurred in main: [Errno 2] No such file or directory: 'emotion_datasets_predicted.csv'
Traceback: Traceback (most recent call last):
  File "c:\xampp\htdocs\PilarEaseDJO\data\translation\data-translation.py", line 187, in main
    df = pd.read_csv(dataset_path)
         ^^^^^^^^^^^^^^^^^^^^^^^^^
  File "C:\xampp\htdocs\PilarEaseDJO\.venv\Lib\site-packages\pandas\io\parsers\readers.py", line 1026, in read_csv
    return _read(filepath_or_buffer, kwds)
           ^^^^^^^^^^^^^^^^^^^^^^^^^^^^^^^
  File "C:\xampp\htdocs\PilarEaseDJO\.venv\Lib\site-packages\pandas\io\parsers\readers.py", line 620, in _read
    parser = TextFileReader(filepath_or_buffer, **kwds)
             ^^^^^^^^^^^^^^^^^^^^^^^^^^^^^^^^^^^^^^^^^^
  File "C:\xampp\htdocs\PilarEaseDJO\.venv\Lib\site-packages\pandas\io\parsers\readers.py", line 1620, in __init__
    self._engine = self._make_engine(f, self.engine)
                   ^^^^^^^^^^^^^^^^^^^^^^^^^^^^^^^^^
  File "C:\xampp\htdocs\PilarEaseDJO\.venv\Lib\site-packages\pandas\io\parsers\readers.py", line 1880, in _make_engine
    self.handles = get_handle(
                   ^^^^^^^^^^^
  File "C:\xampp\htdocs\PilarEaseDJO\.venv\Lib\site-packages\pandas\io\common.py", line 873, in get_handle
    handle = open(
             ^^^^^
FileNotFoundError: [Errno 2] No such file or directory: 'emotion_datasets_predicted.csv'

2024-06-22 19:25:28,065:ERROR:An error occurred in main: [Errno 2] No such file or directory: 'emotion_datasets_predicted.csv'
Traceback: Traceback (most recent call last):
  File "c:\xampp\htdocs\PilarEaseDJO\data\translation\data-translation.py", line 187, in main
    df = pd.read_csv(dataset_path)
         ^^^^^^^^^^^^^^^^^^^^^^^^^
  File "C:\xampp\htdocs\PilarEaseDJO\.venv\Lib\site-packages\pandas\io\parsers\readers.py", line 1026, in read_csv
    return _read(filepath_or_buffer, kwds)
           ^^^^^^^^^^^^^^^^^^^^^^^^^^^^^^^
  File "C:\xampp\htdocs\PilarEaseDJO\.venv\Lib\site-packages\pandas\io\parsers\readers.py", line 620, in _read
    parser = TextFileReader(filepath_or_buffer, **kwds)
             ^^^^^^^^^^^^^^^^^^^^^^^^^^^^^^^^^^^^^^^^^^
  File "C:\xampp\htdocs\PilarEaseDJO\.venv\Lib\site-packages\pandas\io\parsers\readers.py", line 1620, in __init__
    self._engine = self._make_engine(f, self.engine)
                   ^^^^^^^^^^^^^^^^^^^^^^^^^^^^^^^^^
  File "C:\xampp\htdocs\PilarEaseDJO\.venv\Lib\site-packages\pandas\io\parsers\readers.py", line 1880, in _make_engine
    self.handles = get_handle(
                   ^^^^^^^^^^^
  File "C:\xampp\htdocs\PilarEaseDJO\.venv\Lib\site-packages\pandas\io\common.py", line 873, in get_handle
    handle = open(
             ^^^^^
FileNotFoundError: [Errno 2] No such file or directory: 'emotion_datasets_predicted.csv'

2024-06-23 21:30:35,631:ERROR:An error occurred in main: [Errno 2] No such file or directory: 'emotion_datasets_predicted.csv'
Traceback: Traceback (most recent call last):
  File "c:\xampp\htdocs\PilarEaseDJO\data\translation\data-translation.py", line 187, in main
    df = pd.read_csv(dataset_path)
         ^^^^^^^^^^^^^^^^^^^^^^^^^
  File "C:\xampp\htdocs\PilarEaseDJO\.venv\Lib\site-packages\pandas\io\parsers\readers.py", line 1026, in read_csv
    return _read(filepath_or_buffer, kwds)
           ^^^^^^^^^^^^^^^^^^^^^^^^^^^^^^^
  File "C:\xampp\htdocs\PilarEaseDJO\.venv\Lib\site-packages\pandas\io\parsers\readers.py", line 620, in _read
    parser = TextFileReader(filepath_or_buffer, **kwds)
             ^^^^^^^^^^^^^^^^^^^^^^^^^^^^^^^^^^^^^^^^^^
  File "C:\xampp\htdocs\PilarEaseDJO\.venv\Lib\site-packages\pandas\io\parsers\readers.py", line 1620, in __init__
    self._engine = self._make_engine(f, self.engine)
                   ^^^^^^^^^^^^^^^^^^^^^^^^^^^^^^^^^
  File "C:\xampp\htdocs\PilarEaseDJO\.venv\Lib\site-packages\pandas\io\parsers\readers.py", line 1880, in _make_engine
    self.handles = get_handle(
                   ^^^^^^^^^^^
  File "C:\xampp\htdocs\PilarEaseDJO\.venv\Lib\site-packages\pandas\io\common.py", line 873, in get_handle
    handle = open(
             ^^^^^
FileNotFoundError: [Errno 2] No such file or directory: 'emotion_datasets_predicted.csv'

